Workbook
Name tbl: matches[#All]
Name tbldeliveries: deliveries[#All]
Name tblmatches: matches[#All]

Sheet raw data_matches 
A1: match_id | B1: match_date | C1: venue | D1: team1 | E1: team2 | F1: stage | G1: toss_winner | H1: toss_decision | I1: first_ings_score | J1: first_ings_wkts | K1: second_ings_score | L1: second_ings_wkts | M1: match_result | N1: match_winner | O1: wb_runs | P1: wb_wickets | Q1: balls_left | R1: player_of_the_match | S1: top_scorer | T1: highscore | U1: best_bowling | V1: best_bowling_figure | W1: super_over_match | X1: MI_Opponent
A2: 1 | B2: 46109 | C2: M. Chinnaswamy Stadium, Bangalore | D2: RCB | E2: SRH | F2: League | G2: RCB | H2: Bowl | I2: 201 | J2: 9 | K2: 203 | L2: 4 | M2: completed | N2: RCB | P2: 6 | Q2: 26 | R2: Jacob Duffy | S2: Ishan Kishan | T2: 80 | U2: Jacob Duffy | V2: 3--22 | W2: No | X2: =IF(matches[[#This Row],[team1]]="MI",matches[[#This Row],[team2]],IF(matches[[#This Row],[team2]]="MI",matches[[#This Row],[team1]],""))
A3: 2 | B3: 46110 | C3: Wankhede Stadium, Mumbai | D3: MI | E3: KKR | F3: League | G3: MI | H3: Bowl | I3: 220 | J3: 4 | K3: 224 | L3: 4 | M3: completed | N3: MI | P3: 6 | Q3: 5 | R3: Shardul Thakur | S3: Ryan Rickelton | T3: 81 | U3: Shardul Thakur | V3: 3--39 | W3: No | X3: =IF(matches[[#This Row],[team1]]="MI",matches[[#This Row],[team2]],IF(matches[[#This Row],[team2]]="MI",matches[[#This Row],[team1]],"")) -> KKR
A4: 3 | B4: 46111 | C4: Barsapara Stadium, Guwahati | D4: RR | E4: CSK | F4: League | G4: RR | H4: Bowl | I4: 127 | J4: 10 | K4: 128 | L4: 2 | M4: completed | N4: RR | P4: 8 | Q4: 47 | R4: Nandre Burger | S4: Vaibhav Sooryavanshi | T4: 52 | U4: Jofra Archer | V4: 2--19 | W4: No | X4: =IF(matches[[#This Row],[team1]]="MI",matches[[#This Row],[team2]],IF(matches[[#This Row],[team2]]="MI",matches[[#This Row],[team1]],""))
A5: 4 | B5: 46112 | C5: New PCA Cricket Stadium, Mullanpur | D5: PBKS | E5: GT | F5: League | G5: PBKS | H5: Bowl | I5: 162 | J5: 6 | K5: 165 | L5: 7 | M5: completed | N5: PBKS | P5: 3 | Q5: 5 | R5: Cooper Connolly | S5: Cooper Connolly | T5: 72 | U5: Prasidh Krishna | V5: 3--29 | W5: No | X5: =IF(matches[[#This Row],[team1]]="MI",matches[[#This Row],[team2]],IF(matches[[#This Row],[team2]]="MI",matches[[#This Row],[team1]],""))
A6: 5 | B6: 46113 | C6: Ekana Cricket Stadium, Lucknow | D6: LSG | E6: DC | F6: League | G6: DC | H6: Bowl | I6: 141 | J6: 10 | K6: 145 | L6: 4 | M6: completed | N6: DC | P6: 6 | Q6: 17 | R6: Sameer Rizvi | S6: Sameer Rizvi | T6: 70 | U6: Lungi Ngidi | V6: 3--27 | W6: No | X6: =IF(matches[[#This Row],[team1]]="MI",matches[[#This Row],[team2]],IF(matches[[#This Row],[team2]]="MI",matches[[#This Row],[team1]],""))
A7: 6 | B7: 46114 | C7: Eden Gardens, Kolkata | D7: KKR | E7: SRH | F7: League | G7: KKR | H7: Bowl | I7: 226 | J7: 8 | K7: 161 | L7: 10 | M7: completed | N7: SRH | O7: 65 | Q7: 24 | R7: Nitish Kumar Reddy | S7: Angkrish Raghuvanshi | T7: 52 | U7: Blessing Muzarabani | V7: 4--41 | W7: No | X7: =IF(matches[[#This Row],[team1]]="MI",matches[[#This Row],[team2]],IF(matches[[#This Row],[team2]]="MI",matches[[#This Row],[team1]],""))
A8: 7 | B8: 46115 | C8: MA Chidambaram Stadium, Chennai | D8: CSK | E8: PBKS | F8: League | G8: PBKS | H8: Bowl | I8: 209 | J8: 5 | K8: 210 | L8: 5 | M8: completed | N8: PBKS | P8: 5 | Q8: 8 | R8: Priyansh Arya | S8: Ayush Matre | T8: 73 | U8: Vijaykumar Vyshak | V8: 2--38 | W8: No | X8: =IF(matches[[#This Row],[team1]]="MI",matches[[#This Row],[team2]],IF(matches[[#This Row],[team2]]="MI",matches[[#This Row],[team1]],""))
A9: 8 | B9: 46116 | C9: Arun Jaitley Stadium, Delhi | D9: DC | E9: MI | F9: League | G9: DC | H9: Bowl | I9: 162 | J9: 6 | K9: 164 | L9: 4 | M9: completed | N9: DC | P9: 6 | Q9: 11 | R9: Sameer Rizvi | S9: Sameer Rizvi | T9: 90 | U9: Mukesh Kumar | V9: 2--26 | W9: No | X9: =IF(matches[[#This Row],[team1]]="MI",matches[[#This Row],[team2]],IF(matches[[#This Row],[team2]]="MI",matches[[#This Row],[team1]],"")) -> DC
A10: 9 | B10: 46116 | C10: Narendra Modi Stadium, Ahmedabad | D10: GT | E10: RR | F10: League | G10: RR | H10: Bat | I10: 210 | J10: 6 | K10: 204 | L10: 8 | M10: completed | N10: RR | O10: 6 | Q10: 0 | R10: Ravi Bishnoi | S10: Dhruv Jurel | T10: 75 | U10: Ravi Bishnoi | V10: 4--41 | W10: No | X10: =IF(matches[[#This Row],[team1]]="MI",matches[[#This Row],[team2]],IF(matches[[#This Row],[team2]]="MI",matches[[#This Row],[team1]],""))
A11: 10 | B11: 46117 | C11: Rajiv Gandhi International Stadium, Hyderabad | D11: SRH | E11: LSG | F11: League | G11: LSG | H11: Bowl | I11: 156 | J11: 9 | K11: 160 | L11: 5 | M11: completed | N11: LSG | P11: 5 | Q11: 1 | R11: Mohammed Shami | S11: Rishabh Pant | T11: 68 | U11: Mohammed Shami | V11: 2--9 | W11: No | X11: =IF(matches[[#This Row],[team1]]="MI",matches[[#This Row],[team2]],IF(matches[[#This Row],[team2]]="MI",matches[[#This Row],[team1]],""))
A12: 11 | B12: 46117 | C12: M. Chinnaswamy Stadium, Bangalore | D12: RCB | E12: CSK | F12: League | G12: CSK | H12: Bowl | I12: 250 | J12: 3 | K12: 207 | L12: 10 | M12: completed | N12: RCB | O12: 43 | Q12: 2 | R12: Tim David | S12: Tim David | T12: 70 | U12: Bhuvneshwar Kumar | V12: 3--41 | W12: No | X12: =IF(matches[[#This Row],[team1]]="MI",matches[[#This Row],[team2]],IF(matches[[#This Row],[team2]]="MI",matches[[#This Row],[team1]],""))
A13: 12 | B13: 46118 | C13: Eden Gardens, Kolkata | D13: KKR | E13: PBKS | F13: League | G13: KKR | H13: Bat | M13: abandoned | W13: No | X13: =IF(matches[[#This Row],[team1]]="MI",matches[[#This Row],[team2]],IF(matches[[#This Row],[team2]]="MI",matches[[#This Row],[team1]],""))
A14: 13 | B14: 46119 | C14: Barsapara Stadium, Guwahati | D14: RR | E14: MI | F14: League | G14: MI | H14: Bowl | I14: 150 | J14: 3 | K14: 123 | L14: 9 | M14: completed | N14: RR | O14: 27 | Q14: 0 | R14: Yashasvi Jaiswal | S14: Yashasvi Jaiswal | T14: 77 | U14: Sandeep Sharma | V14: 2--26 | W14: No | X14: =IF(matches[[#This Row],[team1]]="MI",matches[[#This Row],[team2]],IF(matches[[#This Row],[team2]]="MI",matches[[#This Row],[team1]],"")) -> RR
A15: 14 | B15: 46120 | C15: Arun Jaitley Stadium, Delhi | D15: DC | E15: GT | F15: League | G15: DC | H15: Bowl | I15: 210 | J15: 4 | K15: 209 | L15: 8 | M15: completed | N15: GT | O15: 1 | Q15: 0 | R15: Rashid Khan | S15: KL Rahul | T15: 92 | U15: Rashid Khan | V15: 3--17 | W15: No | X15: =IF(matches[[#This Row],[team1]]="MI",matches[[#This Row],[team2]],IF(matches[[#This Row],[team2]]="MI",matches[[#This Row],[team1]],""))
A16: 15 | B16: 46121 | C16: Eden Gardens, Kolkata | D16: KKR | E16: LSG | F16: League | G16: LSG | H16: Bowl | I16: 181 | J16: 4 | K16: 182 | L16: 7 | M16: completed | N16: LSG | P16: 3 | Q16: 0 | R16: Mukul Choudhary | S16: Mukul Choudhary | T16: 54 | U16: Anukul Roy | V16: 2--32 | W16: No | X16: =IF(matches[[#This Row],[team1]]="MI",matches[[#This Row],[team2]],IF(matches[[#This Row],[team2]]="MI",matches[[#This Row],[team1]],""))
A17: 16 | B17: 46122 | C17: Barsapara Stadium, Guwahati | D17: RR | E17: RCB | F17: League | G17: RR | H17: Bowl | I17: 201 | J17: 8 | K17: 202 | L17: 4 | M17: completed | N17: RR | P17: 6 | Q17: 12 | R17: Vaibhav Sooryavanshi | S17: Dhruv Jurel | T17: 81 | U17: Krunal Pandya | V17: 2--30 | W17: No | X17: =IF(matches[[#This Row],[team1]]="MI",matches[[#This Row],[team2]],IF(matches[[#This Row],[team2]]="MI",matches[[#This Row],[team1]],""))
A18: 17 | B18: 46123 | C18: New PCA Cricket Stadium, Mullanpur | D18: PBKS | E18: SRH | F18: League | G18: PBKS | H18: Bowl | I18: 219 | J18: 6 | K18: 223 | L18: 4 | M18: completed | N18: PBKS | P18: 6 | Q18: 7 | R18: Shreyas Iyer | S18: Abhishek Sharma | T18: 74 | U18: Shivang Kumar | V18: 3--33 | W18: No | X18: =IF(matches[[#This Row],[team1]]="MI",matches[[#This Row],[team2]],IF(matches[[#This Row],[team2]]="MI",matches[[#This Row],[team1]],""))
A19: 18 | B19: 46123 | C19: MA Chidambaram Stadium, Chennai | D19: CSK | E19: DC | F19: League | G19: DC | H19: Bowl | I19: 212 | J19: 2 | K19: 189 | L19: 10 | M19: completed | N19: CSK | O19: 23 | Q19: 0 | R19: Sanju Samson | S19: Sanju Samson | T19: 115 | U19: Jamie Overton | V19: 4--18 | W19: No | X19: =IF(matches[[#This Row],[team1]]="MI",matches[[#This Row],[team2]],IF(matches[[#This Row],[team2]]="MI",matches[[#This Row],[team1]],""))
A20: 19 | B20: 46124 | C20: Ekana Cricket Stadium, Lucknow | D20: LSG | E20: GT | F20: League | G20: GT | H20: Bowl | I20: 164 | J20: 8 | K20: 165 | L20: 3 | M20: completed | N20: GT | P20: 7 | Q20: 8 | R20: Prasidh Krishna | S20: Jos Buttler | T20: 60 | U20: Prasidh Krishna | V20: 4--28 | W20: No | X20: =IF(matches[[#This Row],[team1]]="MI",matches[[#This Row],[team2]],IF(matches[[#This Row],[team2]]="MI",matches[[#This Row],[team1]],""))
A21: 20 | B21: 46124 | C21: Wankhede Stadium, Mumbai | D21: MI | E21: RCB | F21: League | G21: MI | H21: Bowl | I21: 240 | J21: 4 | K21: 222 | L21: 5 | M21: completed | N21: RCB | O21: 18 | Q21: 0 | R21: Phil Salt | S21: Phil Salt | T21: 78 | U21: Suyash Sharma | V21: 2--47 | W21: No | X21: =IF(matches[[#This Row],[team1]]="MI",matches[[#This Row],[team2]],IF(matches[[#This Row],[team2]]="MI",matches[[#This Row],[team1]],"")) -> RCB
A22: 21 | B22: 46125 | C22: Rajiv Gandhi International Stadium, Hyderabad | D22: SRH | E22: RR | F22: League | G22: RR | H22: Bowl | I22: 216 | J22: 6 | K22: 159 | L22: 10 | M22: completed | N22: SRH | O22: 57 | Q22: 6 | R22: Praful Hinge | S22: Ishan Kishan | T22: 91 | U22: Sakib Hussain | V22: 4--24 | W22: No | X22: =IF(matches[[#This Row],[team1]]="MI",matches[[#This Row],[team2]],IF(matches[[#This Row],[team2]]="MI",matches[[#This Row],[team1]],""))
A23: 22 | B23: 46126 | C23: MA Chidambaram Stadium, Chennai | D23: CSK | E23: KKR | F23: League | G23: KKR | H23: Bowl | I23: 192 | J23: 5 | K23: 160 | L23: 7 | M23: completed | N23: CSK | O23: 32 | Q23: 0 | R23: Noor Ahmad | S23: Sanju Samson | T23: 48 | U23: Noor Ahmad | V23: 3--21 | W23: No | X23: =IF(matches[[#This Row],[team1]]="MI",matches[[#This Row],[team2]],IF(matches[[#This Row],[team2]]="MI",matches[[#This Row],[team1]],""))
A24: 23 | B24: 46127 | C24: M. Chinnaswamy Stadium, Bangalore | D24: RCB | E24: LSG | F24: League | G24: RCB | H24: Bowl | I24: 146 | J24: 10 | K24: 149 | L24: 5 | M24: completed | N24: RCB | P24: 5 | Q24: 29 | R24: Josh Hazlewood | S24: Virat Kohli | T24: 49 | U24: Rasikh Salam | V24: 4--24 | W24: No | X24: =IF(matches[[#This Row],[team1]]="MI",matches[[#This Row],[team2]],IF(matches[[#This Row],[team2]]="MI",matches[[#This Row],[team1]],""))
A25: 24 | B25: 46128 | C25: Wankhede Stadium, Mumbai | D25: MI | E25: PBKS | F25: League | G25: PBKS | H25: Bowl | I25: 195 | J25: 6 | K25: 198 | L25: 3 | M25: completed | N25: PBKS | P25: 7 | Q25: 21 | R25: Arshdeep Singh | S25: Quinton de Kock | T25: 112 | U25: Arshdeep Singh | V25: 3--22 | W25: No | X25: =IF(matches[[#This Row],[team1]]="MI",matches[[#This Row],[team2]],IF(matches[[#This Row],[team2]]="MI",matches[[#This Row],[team1]],"")) -> PBKS
A26: 25 | B26: 46129 | C26: Narendra Modi Stadium, Ahmedabad | D26: GT | E26: KKR | F26: League | G26: KKR | H26: Bat | I26: 180 | J26: 10 | K26: 181 | L26: 5 | M26: completed | N26: GT | P26: 5 | Q26: 2 | R26: Shubman Gill | S26: Shubman Gill | T26: 86 | U26: Kagiso Rabada | V26: 3--29 | W26: No | X26: =IF(matches[[#This Row],[team1]]="MI",matches[[#This Row],[team2]],IF(matches[[#This Row],[team2]]="MI",matches[[#This Row],[team1]],""))
A27: 26 | B27: 46130 | C27: M. Chinnaswamy Stadium, Bangalore | D27: RCB | E27: DC | F27: League | G27: DC | H27: Bowl | I27: 175 | J27: 8 | K27: 179 | L27: 4 | M27: completed | N27: DC | P27: 6 | Q27: 1 | R27: Tristan Stubbs | S27: Phil Salt | T27: 63 | U27: Bhuvneshwar Kumar | V27: 3--26 | W27: No | X27: =IF(matches[[#This Row],[team1]]="MI",matches[[#This Row],[team2]],IF(matches[[#This Row],[team2]]="MI",matches[[#This Row],[team1]],""))
A28: 27 | B28: 46130 | C28: Rajiv Gandhi International Stadium, Hyderabad | D28: SRH | E28: CSK | F28: League | G28: CSK | H28: Bowl | I28: 194 | J28: 9 | K28: 184 | L28: 8 | M28: completed | N28: SRH | O28: 10 | Q28: 0 | R28: Eshan Malinga | S28: Abhishek Sharma | T28: 59 | U28: Eshan Malinga | V28: 3--29 | W28: No | X28: =IF(matches[[#This Row],[team1]]="MI",matches[[#This Row],[team2]],IF(matches[[#This Row],[team2]]="MI",matches[[#This Row],[team1]],""))
A29: 28 | B29: 46131 | C29: Eden Gardens, Kolkata | D29: KKR | E29: RR | F29: League | G29: RR | H29: Bat | I29: 155 | J29: 9 | K29: 161 | L29: 6 | M29: completed | N29: KKR | P29: 4 | Q29: 2 | R29: Varun Chakravarthy | S29: Rinku Singh | T29: 53 | U29: Varun Chakravarthy | V29: 3--14 | W29: No | X29: =IF(matches[[#This Row],[team1]]="MI",matches[[#This Row],[team2]],IF(matches[[#This Row],[team2]]="MI",matches[[#This Row],[team1]],""))
A30: 29 | B30: 46131 | C30: New PCA Cricket Stadium, Mullanpur | D30: PBKS | E30: LSG | F30: League | G30: LSG | H30: Bowl | I30: 254 | J30: 7 | K30: 200 | L30: 5 | M30: completed | N30: PBKS | O30: 54 | Q30: 0 | R30: Priyansh Arya | S30: Priyansh Arya | T30: 93 | U30: Prince Yadav | V30: 2--25 | W30: No | X30: =IF(matches[[#This Row],[team1]]="MI",matches[[#This Row],[team2]],IF(matches[[#This Row],[team2]]="MI",matches[[#This Row],[team1]],""))
A31: 30 | B31: 46132 | C31: Narendra Modi Stadium, Ahmedabad | D31: GT | E31: MI | F31: League | G31: GT | H31: Bowl | I31: 199 | J31: 5 | K31: 100 | L31: 10 | M31: completed | N31: MI | O31: 99 | Q31: 25 | R31: Tilak Varma | S31: Tilak Varma | T31: 101 | U31: Ashwani Kumar | V31: 4--24 | W31: No | X31: =IF(matches[[#This Row],[team1]]="MI",matches[[#This Row],[team2]],IF(matches[[#This Row],[team2]]="MI",matches[[#This Row],[team1]],"")) -> GT
A32: 31 | B32: 46133 | C32: Rajiv Gandhi International Stadium, Hyderabad | D32: SRH | E32: DC | F32: League | G32: DC | H32: Bowl | I32: 242 | J32: 2 | K32: 195 | L32: 9 | M32: completed | N32: SRH | O32: 47 | Q32: 0 | R32: Abhishek Sharma | S32: Abhishek Sharma | T32: 135 | U32: Eshan Malinga | V32: 4--32 | W32: No | X32: =IF(matches[[#This Row],[team1]]="MI",matches[[#This Row],[team2]],IF(matches[[#This Row],[team2]]="MI",matches[[#This Row],[team1]],""))
A33: 32 | B33: 46134 | C33: Ekana Cricket Stadium, Lucknow | D33: LSG | E33: RR | F33: League | G33: LSG | H33: Bowl | I33: 159 | J33: 6 | K33: 119 | L33: 10 | M33: completed | N33: LSG | O33: 40 | Q33: 12 | R33: Ravindra Jadeja | S33: Mitchell Marsh | T33: 55 | U33: Jofra Archer | V33: 3--20 | W33: No | X33: =IF(matches[[#This Row],[team1]]="MI",matches[[#This Row],[team2]],IF(matches[[#This Row],[team2]]="MI",matches[[#This Row],[team1]],""))
A34: 33 | B34: 46135 | C34: Wankhede Stadium, Mumbai | D34: MI | E34: CSK | F34: League | G34: MI | H34: Bowl | I34: 207 | J34: 6 | K34: 104 | L34: 10 | M34: completed | N34: CSK | O34: 103 | Q34: 6 | R34: Sanju Samson | S34: Sanju Samson | T34: 101 | U34: Akeal Hosein | V34: 4--17 | W34: No | X34: =IF(matches[[#This Row],[team1]]="MI",matches[[#This Row],[team2]],IF(matches[[#This Row],[team2]]="MI",matches[[#This Row],[team1]],"")) -> CSK
A35: 34 | B35: 46136 | C35: M. Chinnaswamy Stadium, Bangalore | D35: RCB | E35: GT | F35: League | G35: RCB | H35: Bowl | I35: 205 | J35: 3 | K35: 206 | L35: 5 | M35: completed | N35: RCB | P35: 5 | Q35: 7 | R35: Virat Kohli | S35: Sai Sudarshan | T35: 100 | U35: Rashid Khan | V35: 2--49 | W35: No | X35: =IF(matches[[#This Row],[team1]]="MI",matches[[#This Row],[team2]],IF(matches[[#This Row],[team2]]="MI",matches[[#This Row],[team1]],""))
A36: 35 | B36: 46137 | C36: Arun Jaitley Stadium, Delhi | D36: DC | E36: PBKS | F36: League | G36: DC | H36: Bat | I36: 264 | J36: 2 | K36: 265 | L36: 4 | M36: completed | N36: PBKS | P36: 6 | Q36: 7 | R36: KL Rahul | S36: KL Rahul | T36: 152 | U36: Kuldeep Yadav | V36: 2--46 | W36: No | X36: =IF(matches[[#This Row],[team1]]="MI",matches[[#This Row],[team2]],IF(matches[[#This Row],[team2]]="MI",matches[[#This Row],[team1]],""))
A37: 36 | B37: 46137 | C37: Sawai Mansingh Stadium, Jaipur | D37: RR | E37: SRH | F37: League | G37: SRH | H37: Bowl | I37: 228 | J37: 6 | K37: 229 | L37: 5 | M37: completed | N37: SRH | P37: 5 | Q37: 9 | R37: Ishan Kishan | S37: Vaibhav Sooryavanshi | T37: 103 | U37: Jofra Archer | V37: 2--34 | W37: No | X37: =IF(matches[[#This Row],[team1]]="MI",matches[[#This Row],[team2]],IF(matches[[#This Row],[team2]]="MI",matches[[#This Row],[team1]],""))
A38: 37 | B38: 46138 | C38: Narendra Modi Stadium, Ahmedabad | D38: GT | E38: CSK | F38: League | G38: GT | H38: Bowl | I38: 158 | J38: 7 | K38: 162 | L38: 2 | M38: completed | N38: GT | P38: 8 | Q38: 20 | R38: Kagiso Rabada | S38: Sai Sudarshan | T38: 87 | U38: Kagiso Rabada | V38: 3--25 | W38: No | X38: =IF(matches[[#This Row],[team1]]="MI",matches[[#This Row],[team2]],IF(matches[[#This Row],[team2]]="MI",matches[[#This Row],[team1]],""))
A39: 38 | B39: 46138 | C39: Ekana Cricket Stadium, Lucknow | D39: LSG | E39: KKR | F39: League | G39: LSG | H39: Bowl | I39: 155 | J39: 7 | K39: 155 | L39: 8 | M39: completed | N39: KKR | Q39: 5 | R39: Rinku Singh | S39: Rinku Singh | T39: 83 | U39: Mohsin Khan | V39: 5--23 | W39: Yes | X39: =IF(matches[[#This Row],[team1]]="MI",matches[[#This Row],[team2]],IF(matches[[#This Row],[team2]]="MI",matches[[#This Row],[team1]],""))
A40: 39 | B40: 46139 | C40: Arun Jaitley Stadium, Delhi | D40: DC | E40: RCB | F40: League | G40: RCB | H40: Bowl | I40: 75 | J40: 10 | K40: 77 | L40: 1 | M40: completed | N40: RCB | P40: 9 | Q40: 81 | R40: Josh Hazlewood | S40: Devdutt Padikkal | T40: 34 | U40: Josh Hazlewood | V40: 4--12 | W40: No | X40: =IF(matches[[#This Row],[team1]]="MI",matches[[#This Row],[team2]],IF(matches[[#This Row],[team2]]="MI",matches[[#This Row],[team1]],""))

Sheet raw data_deliveries
A1: match_no | B1: match_date | C1: stage | D1: venue | E1: batting_team | F1: bowling_team | G1: innings | H1: over | I1: striker | J1: bowler | K1: runs_of_bat | L1: extras | M1: wide | N1: legbyes | O1: byes | P1: noballs | Q1: wicket_type | R1: player_dismissed | S1: fielder | T1: MI_Result
A2: 1 | B2: 46109 | C2: League stage | D2: M.Chinnaswamy Stadium, Bengaluru | E2: SRH | F2: RCB | G2: 1 | H2: 0.1 | I2: Travis Head | J2: Jacob Duffy | K2: 0 | L2: 0 | M2: 0 | N2: 0 | O2: 0 | P2: 0 | T2: =_xlfn.XLOOKUP(A2,MI_Match_Analysis!$A$2:$A$8,MI_Match_Analysis!$F$2:$F$8,"Not Found") -> Not Found
A3: 1 | B3: 46109 | C3: League stage | D3: M.Chinnaswamy Stadium, Bengaluru | E3: SRH | F3: RCB | G3: 1 | H3: 0.2 | I3: Travis Head | J3: Jacob Duffy | K3: 1 | L3: 0 | M3: 0 | N3: 0 | O3: 0 | P3: 0 | T3: =_xlfn.XLOOKUP(A3,MI_Match_Analysis!$A$2:$A$8,MI_Match_Analysis!$F$2:$F$8,"Not Found") -> Not Found
A4: 1 | B4: 46109 | C4: League stage | D4: M.Chinnaswamy Stadium, Bengaluru | E4: SRH | F4: RCB | G4: 1 | H4: 0.3 | I4: Abhishek Sharma | J4: Jacob Duffy | K4: 0 | L4: 0 | M4: 0 | N4: 0 | O4: 0 | P4: 0 | T4: =_xlfn.XLOOKUP(A4,MI_Match_Analysis!$A$2:$A$8,MI_Match_Analysis!$F$2:$F$8,"Not Found") -> Not Found
A5: 1 | B5: 46109 | C5: League stage | D5: M.Chinnaswamy Stadium, Bengaluru | E5: SRH | F5: RCB | G5: 1 | H5: 0.4 | I5: Abhishek Sharma | J5: Jacob Duffy | K5: 6 | L5: 0 | M5: 0 | N5: 0 | O5: 0 | P5: 0 | T5: =_xlfn.XLOOKUP(A5,MI_Match_Analysis!$A$2:$A$8,MI_Match_Analysis!$F$2:$F$8,"Not Found") -> Not Found
A6: 1 | B6: 46109 | C6: League stage | D6: M.Chinnaswamy Stadium, Bengaluru | E6: SRH | F6: RCB | G6: 1 | H6: 0.5 | I6: Abhishek Sharma | J6: Jacob Duffy | K6: 0 | L6: 0 | M6: 0 | N6: 0 | O6: 0 | P6: 0 | T6: =_xlfn.XLOOKUP(A6,MI_Match_Analysis!$A$2:$A$8,MI_Match_Analysis!$F$2:$F$8,"Not Found") -> Not Found
A7: 1 | B7: 46109 | C7: League stage | D7: M.Chinnaswamy Stadium, Bengaluru | E7: SRH | F7: RCB | G7: 1 | H7: 0.6 | I7: Abhishek Sharma | J7: Jacob Duffy | K7: 0 | L7: 0 | M7: 0 | N7: 0 | O7: 0 | P7: 0 | T7: =_xlfn.XLOOKUP(A7,MI_Match_Analysis!$A$2:$A$8,MI_Match_Analysis!$F$2:$F$8,"Not Found") -> Not Found
A8: 1 | B8: 46109 | C8: League stage | D8: M.Chinnaswamy Stadium, Bengaluru | E8: SRH | F8: RCB | G8: 1 | H8: 1.1 | I8: Travis Head | J8: Bhuvneshwar Kumar | K8: 1 | L8: 0 | M8: 0 | N8: 0 | O8: 0 | P8: 0 | T8: =_xlfn.XLOOKUP(A8,MI_Match_Analysis!$A$2:$A$8,MI_Match_Analysis!$F$2:$F$8,"Not Found") -> Not Found
A9: 1 | B9: 46109 | C9: League stage | D9: M.Chinnaswamy Stadium, Bengaluru | E9: SRH | F9: RCB | G9: 1 | H9: 1.2 | I9: Abhishek Sharma | J9: Bhuvneshwar Kumar | K9: 1 | L9: 0 | M9: 0 | N9: 0 | O9: 0 | P9: 0 | T9: =_xlfn.XLOOKUP(A9,MI_Match_Analysis!$A$2:$A$8,MI_Match_Analysis!$F$2:$F$8,"Not Found") -> Not Found
A10: 1 | B10: 46109 | C10: League stage | D10: M.Chinnaswamy Stadium, Bengaluru | E10: SRH | F10: RCB | G10: 1 | H10: 1.3 | I10: Travis Head | J10: Bhuvneshwar Kumar | K10: 1 | L10: 0 | M10: 0 | N10: 0 | O10: 0 | P10: 0 | T10: =_xlfn.XLOOKUP(A10,MI_Match_Analysis!$A$2:$A$8,MI_Match_Analysis!$F$2:$F$8,"Not Found") -> Not Found
A11: 1 | B11: 46109 | C11: League stage | D11: M.Chinnaswamy Stadium, Bengaluru | E11: SRH | F11: RCB | G11: 1 | H11: 1.4 | I11: Abhishek Sharma | J11: Bhuvneshwar Kumar | K11: 0 | L11: 0 | M11: 0 | N11: 0 | O11: 0 | P11: 0 | T11: =_xlfn.XLOOKUP(A11,MI_Match_Analysis!$A$2:$A$8,MI_Match_Analysis!$F$2:$F$8,"Not Found") -> Not Found
A12: 1 | B12: 46109 | C12: League stage | D12: M.Chinnaswamy Stadium, Bengaluru | E12: SRH | F12: RCB | G12: 1 | H12: 1.4 | I12: Abhishek Sharma | J12: Bhuvneshwar Kumar | K12: 0 | L12: 1 | M12: 1 | N12: 0 | O12: 0 | P12: 0 | T12: =_xlfn.XLOOKUP(A12,MI_Match_Analysis!$A$2:$A$8,MI_Match_Analysis!$F$2:$F$8,"Not Found") -> Not Found
A13: 1 | B13: 46109 | C13: League stage | D13: M.Chinnaswamy Stadium, Bengaluru | E13: SRH | F13: RCB | G13: 1 | H13: 1.5 | I13: Abhishek Sharma | J13: Bhuvneshwar Kumar | K13: 0 | L13: 1 | M13: 0 | N13: 1 | O13: 0 | P13: 0 | T13: =_xlfn.XLOOKUP(A13,MI_Match_Analysis!$A$2:$A$8,MI_Match_Analysis!$F$2:$F$8,"Not Found") -> Not Found
... A15: 1 | B15: 46109 | C15: League stage | D15: M.Chinnaswamy Stadium, Bengaluru | E15: SRH | F15: RCB | G15: 1 | H15: 1.6 | I15: Travis Head | J15: Bhuvneshwar Kumar | K15: 4 | L15: 0 | M15: 0 | N15: 0 | O15: 0 | P15: 0 | T15: =_xlfn.XLOOKUP(A15,MI_Match_Analysis!$A$2:$A$8,MI_Match_Analysis!$F$2:$F$8,"Not Found") -> Not Found
A16: 1 | B16: 46109 | C16: League stage | D16: M.Chinnaswamy Stadium, Bengaluru | E16: SRH | F16: RCB | G16: 1 | H16: 2.1 | I16: Abhishek Sharma | J16: Jacob Duffy | K16: 0 | L16: 0 | M16: 0 | N16: 0 | O16: 0 | P16: 0 | Q16: caught | R16: Abhishek Sharma | S16: Jitesh Sharma | T16: =_xlfn.XLOOKUP(A16,MI_Match_Analysis!$A$2:$A$8,MI_Match_Analysis!$F$2:$F$8,"Not Found") -> Not Found
A17: 1 | B17: 46109 | C17: League stage | D17: M.Chinnaswamy Stadium, Bengaluru | E17: SRH | F17: RCB | G17: 1 | H17: 2.1 | I17: Abhishek Sharma | J17: Jacob Duffy | K17: 0 | L17: 1 | M17: 1 | N17: 0 | O17: 0 | P17: 0 | Q17: bowled | T17: =_xlfn.XLOOKUP(A17,MI_Match_Analysis!$A$2:$A$8,MI_Match_Analysis!$F$2:$F$8,"Not Found") -> Not Found
A18: 1 | B18: 46109 | C18: League stage | D18: M.Chinnaswamy Stadium, Bengaluru | E18: SRH | F18: RCB | G18: 1 | H18: 2.1 | I18: Abhishek Sharma | J18: Jacob Duffy | K18: 0 | L18: 1 | M18: 1 | N18: 0 | O18: 0 | P18: 0 | T18: =_xlfn.XLOOKUP(A18,MI_Match_Analysis!$A$2:$A$8,MI_Match_Analysis!$F$2:$F$8,"Not Found") -> Not Found
A19: 1 | B19: 46109 | C19: League stage | D19: M.Chinnaswamy Stadium, Bengaluru | E19: SRH | F19: RCB | G19: 1 | H19: 2.2 | I19: Ishan Kishan | J19: Jacob Duffy | K19: 1 | L19: 0 | M19: 0 | N19: 0 | O19: 0 | P19: 0 | T19: =_xlfn.XLOOKUP(A19,MI_Match_Analysis!$A$2:$A$8,MI_Match_Analysis!$F$2:$F$8,"Not Found") -> Not Found
A20: 1 | B20: 46109 | C20: League stage | D20: M.Chinnaswamy Stadium, Bengaluru | E20: SRH | F20: RCB | G20: 1 | H20: 2.3 | I20: Travis Head | J20: Jacob Duffy | K20: 0 | L20: 0 | M20: 0 | N20: 0 | O20: 0 | P20: 0 | T20: =_xlfn.XLOOKUP(A20,MI_Match_Analysis!$A$2:$A$8,MI_Match_Analysis!$F$2:$F$8,"Not Found") -> Not Found
A21: 1 | B21: 46109 | C21: League stage | D21: M.Chinnaswamy Stadium, Bengaluru | E21: SRH | F21: RCB | G21: 1 | H21: 2.4 | I21: Travis Head | J21: Jacob Duffy | K21: 0 | L21: 0 | M21: 0 | N21: 0 | O21: 0 | P21: 0 | T21: =_xlfn.XLOOKUP(A21,MI_Match_Analysis!$A$2:$A$8,MI_Match_Analysis!$F$2:$F$8,"Not Found") -> Not Found
A22: 1 | B22: 46109 | C22: League stage | D22: M.Chinnaswamy Stadium, Bengaluru | E22: SRH | F22: RCB | G22: 1 | H22: 2.5 | I22: Travis Head | J22: Jacob Duffy | K22: 4 | L22: 0 | M22: 0 | N22: 0 | O22: 0 | P22: 0 | T22: =_xlfn.XLOOKUP(A22,MI_Match_Analysis!$A$2:$A$8,MI_Match_Analysis!$F$2:$F$8,"Not Found") -> Not Found
A23: 1 | B23: 46109 | C23: League stage | D23: M.Chinnaswamy Stadium, Bengaluru | E23: SRH | F23: RCB | G23: 1 | H23: 2.6 | I23: Travis Head | J23: Jacob Duffy | K23: 0 | L23: 0 | M23: 0 | N23: 0 | O23: 0 | P23: 0 | Q23: caught | R23: Travis Head | S23: Phil Salt | T23: =_xlfn.XLOOKUP(A23,MI_Match_Analysis!$A$2:$A$8,MI_Match_Analysis!$F$2:$F$8,"Not Found") -> Not Found
A24: 1 | B24: 46109 | C24: League stage | D24: M.Chinnaswamy Stadium, Bengaluru | E24: SRH | F24: RCB | G24: 1 | H24: 3.1 | I24: Ishan Kishan | J24: Bhuvneshwar Kumar | K24: 4 | L24: 0 | M24: 0 | N24: 0 | O24: 0 | P24: 0 | T24: =_xlfn.XLOOKUP(A24,MI_Match_Analysis!$A$2:$A$8,MI_Match_Analysis!$F$2:$F$8,"Not Found") -> Not Found
A25: 1 | B25: 46109 | C25: League stage | D25: M.Chinnaswamy Stadium, Bengaluru | E25: SRH | F25: RCB | G25: 1 | H25: 3.2 | I25: Ishan Kishan | J25: Bhuvneshwar Kumar | K25: 1 | L25: 0 | M25: 0 | N25: 0 | O25: 0 | P25: 0 | T25: =_xlfn.XLOOKUP(A25,MI_Match_Analysis!$A$2:$A$8,MI_Match_Analysis!$F$2:$F$8,"Not Found") -> Not Found
A26: 1 | B26: 46109 | C26: League stage | D26: M.Chinnaswamy Stadium, Bengaluru | E26: SRH | F26: RCB | G26: 1 | H26: 3.3 | I26: Nitish Reddy | J26: Bhuvneshwar Kumar | K26: 0 | L26: 0 | M26: 0 | N26: 0 | O26: 0 | P26: 0 | T26: =_xlfn.XLOOKUP(A26,MI_Match_Analysis!$A$2:$A$8,MI_Match_Analysis!$F$2:$F$8,"Not Found") -> Not Found
A27: 1 | B27: 46109 | C27: League stage | D27: M.Chinnaswamy Stadium, Bengaluru | E27: SRH | F27: RCB | G27: 1 | H27: 3.4 | I27: Nitish Reddy | J27: Bhuvneshwar Kumar | K27: 0 | L27: 0 | M27: 0 | N27: 0 | O27: 0 | P27: 0 | T27: =_xlfn.XLOOKUP(A27,MI_Match_Analysis!$A$2:$A$8,MI_Match_Analysis!$F$2:$F$8,"Not Found") -> Not Found
A28: 1 | B28: 46109 | C28: League stage | D28: M.Chinnaswamy Stadium, Bengaluru | E28: SRH | F28: RCB | G28: 1 | H28: 3.5 | I28: Nitish Reddy | J28: Bhuvneshwar Kumar | K28: 0 | L28: 0 | M28: 0 | N28: 0 | O28: 0 | P28: 0 | T28: =_xlfn.XLOOKUP(A28,MI_Match_Analysis!$A$2:$A$8,MI_Match_Analysis!$F$2:$F$8,"Not Found") -> Not Found
A29: 1 | B29: 46109 | C29: League stage | D29: M.Chinnaswamy Stadium, Bengaluru | E29: SRH | F29: RCB | G29: 1 | H29: 3.6 | I29: Nitish Reddy | J29: Bhuvneshwar Kumar | K29: 1 | L29: 0 | M29: 0 | N29: 0 | O29: 0 | P29: 0 | T29: =_xlfn.XLOOKUP(A29,MI_Match_Analysis!$A$2:$A$8,MI_Match_Analysis!$F$2:$F$8,"Not Found") -> Not Found
A30: 1 | B30: 46109 | C30: League stage | D30: M.Chinnaswamy Stadium, Bengaluru | E30: SRH | F30: RCB | G30: 1 | H30: 4.1 | I30: Nitish Reddy | J30: Jacob Duffy | K30: 0 | L30: 0 | M30: 0 | N30: 0 | O30: 0 | P30: 0 | T30: =_xlfn.XLOOKUP(A30,MI_Match_Analysis!$A$2:$A$8,MI_Match_Analysis!$F$2:$F$8,"Not Found") -> Not Found
A31: 1 | B31: 46109 | C31: League stage | D31: M.Chinnaswamy Stadium, Bengaluru | E31: SRH | F31: RCB | G31: 1 | H31: 4.2 | I31: Nitish Reddy | J31: Jacob Duffy | K31: 0 | L31: 0 | M31: 0 | N31: 0 | O31: 0 | P31: 0 | Q31: caught | R31: Nitish Reddy | S31: Abhinandan Singh | T31: =_xlfn.XLOOKUP(A31,MI_Match_Analysis!$A$2:$A$8,MI_Match_Analysis!$F$2:$F$8,"Not Found") -> Not Found
A32: 1 | B32: 46109 | C32: League stage | D32: M.Chinnaswamy Stadium, Bengaluru | E32: SRH | F32: RCB | G32: 1 | H32: 4.3 | I32: Heinrich Klaasen | J32: Jacob Duffy | K32: 0 | L32: 0 | M32: 0 | N32: 0 | O32: 0 | P32: 0 | T32: =_xlfn.XLOOKUP(A32,MI_Match_Analysis!$A$2:$A$8,MI_Match_Analysis!$F$2:$F$8,"Not Found") -> Not Found
A33: 1 | B33: 46109 | C33: League stage | D33: M.Chinnaswamy Stadium, Bengaluru | E33: SRH | F33: RCB | G33: 1 | H33: 4.4 | I33: Heinrich Klaasen | J33: Jacob Duffy | K33: 3 | L33: 0 | M33: 0 | N33: 0 | O33: 0 | P33: 0 | T33: =_xlfn.XLOOKUP(A33,MI_Match_Analysis!$A$2:$A$8,MI_Match_Analysis!$F$2:$F$8,"Not Found") -> Not Found
A34: 1 | B34: 46109 | C34: League stage | D34: M.Chinnaswamy Stadium, Bengaluru | E34: SRH | F34: RCB | G34: 1 | H34: 4.5 | I34: Ishan Kishan | J34: Jacob Duffy | K34: 1 | L34: 0 | M34: 0 | N34: 0 | O34: 0 | P34: 0 | T34: =_xlfn.XLOOKUP(A34,MI_Match_Analysis!$A$2:$A$8,MI_Match_Analysis!$F$2:$F$8,"Not Found") -> Not Found
A35: 1 | B35: 46109 | C35: League stage | D35: M.Chinnaswamy Stadium, Bengaluru | E35: SRH | F35: RCB | G35: 1 | H35: 4.6 | I35: Heinrich Klaasen | J35: Jacob Duffy | K35: 0 | L35: 0 | M35: 0 | N35: 0 | O35: 0 | P35: 0 | T35: =_xlfn.XLOOKUP(A35,MI_Match_Analysis!$A$2:$A$8,MI_Match_Analysis!$F$2:$F$8,"Not Found") -> Not Found
A36: 1 | B36: 46109 | C36: League stage | D36: M.Chinnaswamy Stadium, Bengaluru | E36: SRH | F36: RCB | G36: 1 | H36: 5.1 | I36: Ishan Kishan | J36: Abhinandan Singh | K36: 0 | L36: 0 | M36: 0 | N36: 0 | O36: 0 | P36: 0 | T36: =_xlfn.XLOOKUP(A36,MI_Match_Analysis!$A$2:$A$8,MI_Match_Analysis!$F$2:$F$8,"Not Found") -> Not Found
A37: 1 | B37: 46109 | C37: League stage | D37: M.Chinnaswamy Stadium, Bengaluru | E37: SRH | F37: RCB | G37: 1 | H37: 5.2 | I37: Ishan Kishan | J37: Abhinandan Singh | K37: 6 | L37: 0 | M37: 0 | N37: 0 | O37: 0 | P37: 0 | T37: =_xlfn.XLOOKUP(A37,MI_Match_Analysis!$A$2:$A$8,MI_Match_Analysis!$F$2:$F$8,"Not Found") -> Not Found
A38: 1 | B38: 46109 | C38: League stage | D38: M.Chinnaswamy Stadium, Bengaluru | E38: SRH | F38: RCB | G38: 1 | H38: 5.3 | I38: Ishan Kishan | J38: Abhinandan Singh | K38: 4 | L38: 0 | M38: 0 | N38: 0 | O38: 0 | P38: 0 | T38: =_xlfn.XLOOKUP(A38,MI_Match_Analysis!$A$2:$A$8,MI_Match_Analysis!$F$2:$F$8,"Not Found") -> Not Found
A39: 1 | B39: 46109 | C39: League stage | D39: M.Chinnaswamy Stadium, Bengaluru | E39: SRH | F39: RCB | G39: 1 | H39: 5.4 | I39: Ishan Kishan | J39: Abhinandan Singh | K39: 6 | L39: 0 | M39: 0 | N39: 0 | O39: 0 | P39: 0 | T39: =_xlfn.XLOOKUP(A39,MI_Match_Analysis!$A$2:$A$8,MI_Match_Analysis!$F$2:$F$8,"Not Found") -> Not Found
A40: 1 | B40: 46109 | C40: League stage | D40: M.Chinnaswamy Stadium, Bengaluru | E40: SRH | F40: RCB | G40: 1 | H40: 5.5 | I40: Ishan Kishan | J40: Abhinandan Singh | K40: 0 | L40: 0 | M40: 0 | N40: 0 | O40: 0 | P40: 0 | T40: =_xlfn.XLOOKUP(A40,MI_Match_Analysis!$A$2:$A$8,MI_Match_Analysis!$F$2:$F$8,"Not Found") -> Not Found
A41: 1 | B41: 46109 | C41: League stage | D41: M.Chinnaswamy Stadium, Bengaluru | E41: SRH | F41: RCB | G41: 1 | H41: 5.6 | I41: Ishan Kishan | J41: Abhinandan Singh | K41: 0 | L41: 0 | M41: 0 | N41: 0 | O41: 0 | P41: 0 | T41: =_xlfn.XLOOKUP(A41,MI_Match_Analysis!$A$2:$A$8,MI_Match_Analysis!$F$2:$F$8,"Not Found") -> Not Found
...

Sheet MI_Match_Analysis
A1: Match ID | B1: Date | C1: Opponent | D1: Venue | E1: Batting Position | F1: Result | G1: MI Score | H1: Opponent Score | I1: Toss_Winner | J1: Toss_Decision | K1: Player of Match
A2: {=_xlfn._xlws.FILTER(matches[match_id],(matches[team1]="MI")+(matches[team2]="MI"))} -> 2 | B2: {=_xlfn._xlws.FILTER(matches[match_date],(matches[team1]="MI")+(matches[team2]="MI"))} -> 46110 | C2: {=_xlfn._xlws.FILTER(IF(matches[team1]="MI",matches[team2],matches[team1]),(matches[team1]="MI")+(matches[team2]="MI"))} -> KKR | D2: {=_xlfn._xlws.FILTER(matches[venue],(matches[team1]="MI")+(matches[team2]="MI"))} -> Wankhede Stadium, Mumbai | E2: {=_xlfn._xlws.FILTER(IF(((matches[toss_decision]="Bat")*(matches[toss_winner]="MI")+((matches[toss_decision]="Bowl")*(matches[toss_winner]<> "MI")))>0,"Batting First","Chasing"),(matches[team1]="MI")+(matches[team2]="MI"))} -> Chasing | F2: {=_xlfn._xlws.FILTER(IF(matches[match_winner]="MI","Win","Loss"),(matches[team1]="MI")+(matches[team2]="MI"))} -> Win | G2: {=_xlfn._xlws.FILTER(IF(matches[team1]="MI",matches[first_ings_score],matches[second_ings_score]),(matches[team1]="MI")+(matches[team2]="MI"))} -> 220 | H2: {=_xlfn._xlws.FILTER(IF(matches[team1]="MI",matches[second_ings_score],matches[first_ings_score]),(matches[team1]="MI")+(matches[team2]="MI"))} -> 224 | I2: {=_xlfn._xlws.FILTER(matches[toss_winner],(matches[team1]="MI")+(matches[team2]="MI"))} -> MI | J2: {=_xlfn._xlws.FILTER(matches[toss_decision],(matches[team1]="MI")+(matches[team2]="MI"))} -> Bowl | K2: {=_xlfn._xlws.FILTER(matches[player_of_the_match],(matches[team1]="MI")+(matches[team2]="MI"))} -> Shardul Thakur
A3: 8 | B3: 46116 | C3: DC | D3: Arun Jaitley Stadium, Delhi | E3: Batting First | F3: Loss | G3: 164 | H3: 162 | I3: DC | J3: Bowl | K3: Sameer Rizvi
A4: 13 | B4: 46119 | C4: RR | D4: Barsapara Stadium, Guwahati | E4: Chasing | F4: Loss | G4: 123 | H4: 150 | I4: MI | J4: Bowl | K4: Yashasvi Jaiswal
A5: 20 | B5: 46124 | C5: RCB | D5: Wankhede Stadium, Mumbai | E5: Chasing | F5: Loss | G5: 240 | H5: 222 | I5: MI | J5: Bowl | K5: Phil Salt
A6: 24 | B6: 46128 | C6: PBKS | D6: Wankhede Stadium, Mumbai | E6: Batting First | F6: Loss | G6: 195 | H6: 198 | I6: PBKS | J6: Bowl | K6: Arshdeep Singh
A7: 30 | B7: 46132 | C7: GT | D7: Narendra Modi Stadium, Ahmedabad | E7: Batting First | F7: Win | G7: 100 | H7: 199 | I7: GT | J7: Bowl | K7: Tilak Varma
A8: 33 | B8: 46135 | C8: CSK | D8: Wankhede Stadium, Mumbai | E8: Chasing | F8: Loss | G8: 207 | H8: 104 | I8: MI | J8: Bowl | K8: Sanju Samson
A10: Result | B10: Matches | C10: Average MI Score | D10: Average Opponent Score
A11: Win | B11: =COUNTIF($F$2:$F$8,A11) -> 2 | C11: =AVERAGEIF($D$16:$D$22,"Win",$B$16:$B$22) -> 211.5 | D11: =AVERAGEIF($D$16:$D$22,"Win",$C$16:$C$22) -> 160
A12: Loss | B12: =COUNTIF($F$2:$F$8,A12) -> 5 | C12: =AVERAGEIF($D$16:$D$22,"Loss",$B$16:$B$22) -> 161.2 | D12: =AVERAGEIF($D$16:$D$22,"Loss",$C$16:$C$22) -> 191.8
A15: Match | B15: MI Score | C15: Opponent Score | D15: Result | E15: Result | F15: Matches | G15: Percentage
A16: 2 vs KKR | B16: 224 | C16: 220 | D16: Win | E16: Win | F16: 2 | G16: 0.286
A17: 8 vs DC | B17: 162 | C17: 164 | D17: Loss | E17: Loss | F17: 5 | G17: 0.714
A18: 13 vs RR | B18: 123 | C18: 150 | D18: Loss
A19: 20 vs RCB | B19: 222 | C19: 240 | D19: Loss
A20: 24 vs PBKS | B20: 195 | C20: 198 | D20: Loss
A21: 30 vs GT | B21: 199 | C21: 100 | D21: Win
A22: 33 vs CSK | B22: 104 | C22: 207 | D22: Loss
A26: Row Labels
A27: Loss
A28: Win
A29: Grand Total

Sheet MI_Batting_Analysis
A1: Player | B1: Runs | C1: Balls | D1: Strike Rate | E1: 4s | F1: 6s | G1: Dismissals | H1: Batting Average | I1: Runs per Match | K1: Metric | L1: Values
A2: {=_xlfn.UNIQUE(_xlfn._xlws.FILTER(deliveries[striker],(deliveries[batting_team]="MI")*ISNUMBER(_xlfn.XMATCH(deliveries[match_no],_xlfn.ANCHORARRAY(MI_Match_Analysis!$A$2)))))} -> Ryan Rickelton | B2: {=SUMPRODUCT((deliveries[batting_team]="MI")*(deliveries[striker]=$A2)*ISNUMBER(_xlfn.XMATCH(deliveries[match_no],_xlfn.ANCHORARRAY(MI_Match_Analysis!$A$2)))*deliveries[runs_of_bat])} -> 137 | C2: {=SUMPRODUCT((deliveries[batting_team]="MI")*(deliveries[striker]=$A2)*ISNUMBER(_xlfn.XMATCH(deliveries[match_no],_xlfn.ANCHORARRAY(MI_Match_Analysis!$A$2)))*(deliveries[wide]=0))} -> 88 | D2: =IFERROR(B2/C2*100,0) -> 155.68182 | E2: {=SUMPRODUCT((deliveries[batting_team]="MI")*(deliveries[striker]=$A2)*ISNUMBER(_xlfn.XMATCH(deliveries[match_no],_xlfn.ANCHORARRAY(MI_Match_Analysis!$A$2)))*(deliveries[runs_of_bat]=4))} -> 9 | F2: {=SUMPRODUCT((deliveries[batting_team]="MI")*(deliveries[striker]=$A2)*ISNUMBER(_xlfn.XMATCH(deliveries[match_no],_xlfn.ANCHORARRAY(MI_Match_Analysis!$A$2)))*(deliveries[runs_of_bat]=6))} -> 12 | G2: {=SUMPRODUCT((deliveries[batting_team]="MI")*(deliveries[player_dismissed]=$A2)*ISNUMBER(_xlfn.XMATCH(deliveries[match_no],_xlfn.ANCHORARRAY(MI_Match_Analysis!$A$2))))} -> 5 | H2: =IFERROR(B2/G2,0) -> 27.4 | I2: =B2/7 -> 19.571429 | K2: Top Run Scorer | L2: =INDEX($A$2:$A$50,MATCH(MAX($B$2:$B$50),$B$2:$B$50,0)) -> Tilak Varma
A3: Rohit Sharma | B3: {=SUMPRODUCT((deliveries[batting_team]="MI")*(deliveries[striker]=$A3)*ISNUMBER(_xlfn.XMATCH(deliveries[match_no],_xlfn.ANCHORARRAY(MI_Match_Analysis!$A$2)))*deliveries[runs_of_bat])} -> 137 | C3: {=SUMPRODUCT((deliveries[batting_team]="MI")*(deliveries[striker]=$A3)*ISNUMBER(_xlfn.XMATCH(deliveries[match_no],_xlfn.ANCHORARRAY(MI_Match_Analysis!$A$2)))*(deliveries[wide]=0))} -> 83 | D3: =IFERROR(B3/C3*100,0) -> 165.06024 | E3: {=SUMPRODUCT((deliveries[batting_team]="MI")*(deliveries[striker]=$A3)*ISNUMBER(_xlfn.XMATCH(deliveries[match_no],_xlfn.ANCHORARRAY(MI_Match_Analysis!$A$2)))*(deliveries[runs_of_bat]=4))} -> 13 | F3: {=SUMPRODUCT((deliveries[batting_team]="MI")*(deliveries[striker]=$A3)*ISNUMBER(_xlfn.XMATCH(deliveries[match_no],_xlfn.ANCHORARRAY(MI_Match_Analysis!$A$2)))*(deliveries[runs_of_bat]=6))} -> 8 | G3: {=SUMPRODUCT((deliveries[batting_team]="MI")*(deliveries[player_dismissed]=$A3)*ISNUMBER(_xlfn.XMATCH(deliveries[match_no],_xlfn.ANCHORARRAY(MI_Match_Analysis!$A$2))))} -> 4 | H3: =IFERROR(B3/G3,0) -> 34.25 | I3: =B3/7 -> 19.571429 | K3: Highest Strike Rate (30+balls) | L3: {=_xlfn.LET(_xlpm.p,$A$2:$A$50,_xlpm.b,$C$2:$C$50,_xlpm.s,$D$2:$D$50,INDEX(_xlpm.p,MATCH(MAX(_xlfn._xlws.FILTER(_xlpm.s,_xlpm.b>=30)),_xlpm.s,0)))} -> Sherfane Rutherford
A4: Suryakumar Yadav | B4: {=SUMPRODUCT((deliveries[batting_team]="MI")*(deliveries[striker]=$A4)*ISNUMBER(_xlfn.XMATCH(deliveries[match_no],_xlfn.ANCHORARRAY(MI_Match_Analysis!$A$2)))*deliveries[runs_of_bat])} -> 157 | C4: {=SUMPRODUCT((deliveries[batting_team]="MI")*(deliveries[striker]=$A4)*ISNUMBER(_xlfn.XMATCH(deliveries[match_no],_xlfn.ANCHORARRAY(MI_Match_Analysis!$A$2)))*(deliveries[wide]=0))} -> 110 | D4: =IFERROR(B4/C4*100,0) -> 142.72727 | E4: {=SUMPRODUCT((deliveries[batting_team]="MI")*(deliveries[striker]=$A4)*ISNUMBER(_xlfn.XMATCH(deliveries[match_no],_xlfn.ANCHORARRAY(MI_Match_Analysis!$A$2)))*(deliveries[runs_of_bat]=4))} -> 17 | F4: {=SUMPRODUCT((deliveries[batting_team]="MI")*(deliveries[striker]=$A4)*ISNUMBER(_xlfn.XMATCH(deliveries[match_no],_xlfn.ANCHORARRAY(MI_Match_Analysis!$A$2)))*(deliveries[runs_of_bat]=6))} -> 4 | G4: {=SUMPRODUCT((deliveries[batting_team]="MI")*(deliveries[player_dismissed]=$A4)*ISNUMBER(_xlfn.XMATCH(deliveries[match_no],_xlfn.ANCHORARRAY(MI_Match_Analysis!$A$2))))} -> 7 | H4: =IFERROR(B4/G4,0) -> 22.428571 | I4: =B4/7 -> 22.428571 | K4: Most Fours | L4: =INDEX($A$2:$A$50,MATCH(MAX($E$2:$E$50),$E$2:$E$50,0)) -> Tilak Varma
A5: Tilak Varma | B5: {=SUMPRODUCT((deliveries[batting_team]="MI")*(deliveries[striker]=$A5)*ISNUMBER(_xlfn.XMATCH(deliveries[match_no],_xlfn.ANCHORARRAY(MI_Match_Analysis!$A$2)))*deliveries[runs_of_bat])} -> 181 | C5: {=SUMPRODUCT((deliveries[batting_team]="MI")*(deliveries[striker]=$A5)*ISNUMBER(_xlfn.XMATCH(deliveries[match_no],_xlfn.ANCHORARRAY(MI_Match_Analysis!$A$2)))*(deliveries[wide]=0))} -> 106 | D5: =IFERROR(B5/C5*100,0) -> 170.75472 | E5: {=SUMPRODUCT((deliveries[batting_team]="MI")*(deliveries[striker]=$A5)*ISNUMBER(_xlfn.XMATCH(deliveries[match_no],_xlfn.ANCHORARRAY(MI_Match_Analysis!$A$2)))*(deliveries[runs_of_bat]=4))} -> 21 | F5: {=SUMPRODUCT((deliveries[batting_team]="MI")*(deliveries[striker]=$A5)*ISNUMBER(_xlfn.XMATCH(deliveries[match_no],_xlfn.ANCHORARRAY(MI_Match_Analysis!$A$2)))*(deliveries[runs_of_bat]=6))} -> 7 | G5: {=SUMPRODUCT((deliveries[batting_team]="MI")*(deliveries[player_dismissed]=$A5)*ISNUMBER(_xlfn.XMATCH(deliveries[match_no],_xlfn.ANCHORARRAY(MI_Match_Analysis!$A$2))))} -> 6 | H5: =IFERROR(B5/G5,0) -> 30.166667 | I5: =B5/7 -> 25.857143 | K5: Most Sixs | L5: =INDEX($A$2:$A$50,MATCH(MAX($F$2:$F$50),$F$2:$F$50,0)) -> Ryan Rickelton
A6: Hardik Pandya | B6: {=SUMPRODUCT((deliveries[batting_team]="MI")*(deliveries[striker]=$A6)*ISNUMBER(_xlfn.XMATCH(deliveries[match_no],_xlfn.ANCHORARRAY(MI_Match_Analysis!$A$2)))*deliveries[runs_of_bat])} -> 97 | C6: {=SUMPRODUCT((deliveries[batting_team]="MI")*(deliveries[striker]=$A6)*ISNUMBER(_xlfn.XMATCH(deliveries[match_no],_xlfn.ANCHORARRAY(MI_Match_Analysis!$A$2)))*(deliveries[wide]=0))} -> 69 | D6: =IFERROR(B6/C6*100,0) -> 140.57971 | E6: {=SUMPRODUCT((deliveries[batting_team]="MI")*(deliveries[striker]=$A6)*ISNUMBER(_xlfn.XMATCH(deliveries[match_no],_xlfn.ANCHORARRAY(MI_Match_Analysis!$A$2)))*(deliveries[runs_of_bat]=4))} -> 12 | F6: {=SUMPRODUCT((deliveries[batting_team]="MI")*(deliveries[striker]=$A6)*ISNUMBER(_xlfn.XMATCH(deliveries[match_no],_xlfn.ANCHORARRAY(MI_Match_Analysis!$A$2)))*(deliveries[runs_of_bat]=6))} -> 2 | G6: {=SUMPRODUCT((deliveries[batting_team]="MI")*(deliveries[player_dismissed]=$A6)*ISNUMBER(_xlfn.XMATCH(deliveries[match_no],_xlfn.ANCHORARRAY(MI_Match_Analysis!$A$2))))} -> 5 | H6: =IFERROR(B6/G6,0) -> 19.4 | I6: =B6/7 -> 13.857143
A7: Naman Dhir | B7: {=SUMPRODUCT((deliveries[batting_team]="MI")*(deliveries[striker]=$A7)*ISNUMBER(_xlfn.XMATCH(deliveries[match_no],_xlfn.ANCHORARRAY(MI_Match_Analysis!$A$2)))*deliveries[runs_of_bat])} -> 154 | C7: {=SUMPRODUCT((deliveries[batting_team]="MI")*(deliveries[striker]=$A7)*ISNUMBER(_xlfn.XMATCH(deliveries[match_no],_xlfn.ANCHORARRAY(MI_Match_Analysis!$A$2)))*(deliveries[wide]=0))} -> 104 | D7: =IFERROR(B7/C7*100,0) -> 148.07692 | E7: {=SUMPRODUCT((deliveries[batting_team]="MI")*(deliveries[striker]=$A7)*ISNUMBER(_xlfn.XMATCH(deliveries[match_no],_xlfn.ANCHORARRAY(MI_Match_Analysis!$A$2)))*(deliveries[runs_of_bat]=4))} -> 15 | F7: {=SUMPRODUCT((deliveries[batting_team]="MI")*(deliveries[striker]=$A7)*ISNUMBER(_xlfn.XMATCH(deliveries[match_no],_xlfn.ANCHORARRAY(MI_Match_Analysis!$A$2)))*(deliveries[runs_of_bat]=6))} -> 6 | G7: {=SUMPRODUCT((deliveries[batting_team]="MI")*(deliveries[player_dismissed]=$A7)*ISNUMBER(_xlfn.XMATCH(deliveries[match_no],_xlfn.ANCHORARRAY(MI_Match_Analysis!$A$2))))} -> 6 | H7: =IFERROR(B7/G7,0) -> 25.666667 | I7: =B7/7 -> 22
A8: Sherfane Rutherford | B8: {=SUMPRODUCT((deliveries[batting_team]="MI")*(deliveries[striker]=$A8)*ISNUMBER(_xlfn.XMATCH(deliveries[match_no],_xlfn.ANCHORARRAY(MI_Match_Analysis!$A$2)))*deliveries[runs_of_bat])} -> 103 | C8: {=SUMPRODUCT((deliveries[batting_team]="MI")*(deliveries[striker]=$A8)*ISNUMBER(_xlfn.XMATCH(deliveries[match_no],_xlfn.ANCHORARRAY(MI_Match_Analysis!$A$2)))*(deliveries[wide]=0))} -> 54 | D8: =IFERROR(B8/C8*100,0) -> 190.74074 | E8: {=SUMPRODUCT((deliveries[batting_team]="MI")*(deliveries[striker]=$A8)*ISNUMBER(_xlfn.XMATCH(deliveries[match_no],_xlfn.ANCHORARRAY(MI_Match_Analysis!$A$2)))*(deliveries[runs_of_bat]=4))} -> 4 | F8: {=SUMPRODUCT((deliveries[batting_team]="MI")*(deliveries[striker]=$A8)*ISNUMBER(_xlfn.XMATCH(deliveries[match_no],_xlfn.ANCHORARRAY(MI_Match_Analysis!$A$2)))*(deliveries[runs_of_bat]=6))} -> 11 | G8: {=SUMPRODUCT((deliveries[batting_team]="MI")*(deliveries[player_dismissed]=$A8)*ISNUMBER(_xlfn.XMATCH(deliveries[match_no],_xlfn.ANCHORARRAY(MI_Match_Analysis!$A$2))))} -> 4 | H8: =IFERROR(B8/G8,0) -> 25.75 | I8: =B8/7 -> 14.714286
A9: Mitchell Santner | B9: {=SUMPRODUCT((deliveries[batting_team]="MI")*(deliveries[striker]=$A9)*ISNUMBER(_xlfn.XMATCH(deliveries[match_no],_xlfn.ANCHORARRAY(MI_Match_Analysis!$A$2)))*deliveries[runs_of_bat])} -> 26 | C9: {=SUMPRODUCT((deliveries[batting_team]="MI")*(deliveries[striker]=$A9)*ISNUMBER(_xlfn.XMATCH(deliveries[match_no],_xlfn.ANCHORARRAY(MI_Match_Analysis!$A$2)))*(deliveries[wide]=0))} -> 19 | D9: =IFERROR(B9/C9*100,0) -> 136.84211 | E9: {=SUMPRODUCT((deliveries[batting_team]="MI")*(deliveries[striker]=$A9)*ISNUMBER(_xlfn.XMATCH(deliveries[match_no],_xlfn.ANCHORARRAY(MI_Match_Analysis!$A$2)))*(deliveries[runs_of_bat]=4))} -> 3 | F9: {=SUMPRODUCT((deliveries[batting_team]="MI")*(deliveries[striker]=$A9)*ISNUMBER(_xlfn.XMATCH(deliveries[match_no],_xlfn.ANCHORARRAY(MI_Match_Analysis!$A$2)))*(deliveries[runs_of_bat]=6))} -> 0 | G9: {=SUMPRODUCT((deliveries[batting_team]="MI")*(deliveries[player_dismissed]=$A9)*ISNUMBER(_xlfn.XMATCH(deliveries[match_no],_xlfn.ANCHORARRAY(MI_Match_Analysis!$A$2))))} -> 0 | H9: =IFERROR(B9/G9,0) -> 0 | I9: =B9/7 -> 3.7142857
A10: Corbin Bosch | B10: {=SUMPRODUCT((deliveries[batting_team]="MI")*(deliveries[striker]=$A10)*ISNUMBER(_xlfn.XMATCH(deliveries[match_no],_xlfn.ANCHORARRAY(MI_Match_Analysis!$A$2)))*deliveries[runs_of_bat])} -> 11 | C10: {=SUMPRODUCT((deliveries[batting_team]="MI")*(deliveries[striker]=$A10)*ISNUMBER(_xlfn.XMATCH(deliveries[match_no],_xlfn.ANCHORARRAY(MI_Match_Analysis!$A$2)))*(deliveries[wide]=0))} -> 4 | D10: =IFERROR(B10/C10*100,0) -> 275 | E10: {=SUMPRODUCT((deliveries[batting_team]="MI")*(deliveries[striker]=$A10)*ISNUMBER(_xlfn.XMATCH(deliveries[match_no],_xlfn.ANCHORARRAY(MI_Match_Analysis!$A$2)))*(deliveries[runs_of_bat]=4))} -> 2 | F10: {=SUMPRODUCT((deliveries[batting_team]="MI")*(deliveries[striker]=$A10)*ISNUMBER(_xlfn.XMATCH(deliveries[match_no],_xlfn.ANCHORARRAY(MI_Match_Analysis!$A$2)))*(deliveries[runs_of_bat]=6))} -> 0 | G10: {=SUMPRODUCT((deliveries[batting_team]="MI")*(deliveries[player_dismissed]=$A10)*ISNUMBER(_xlfn.XMATCH(deliveries[match_no],_xlfn.ANCHORARRAY(MI_Match_Analysis!$A$2))))} -> 0 | H10: =IFERROR(B10/G10,0) -> 0 | I10: =B10/7 -> 1.5714286
A11: Shardul Thakur | B11: {=SUMPRODUCT((deliveries[batting_team]="MI")*(deliveries[striker]=$A11)*ISNUMBER(_xlfn.XMATCH(deliveries[match_no],_xlfn.ANCHORARRAY(MI_Match_Analysis!$A$2)))*deliveries[runs_of_bat])} -> 14 | C11: {=SUMPRODUCT((deliveries[batting_team]="MI")*(deliveries[striker]=$A11)*ISNUMBER(_xlfn.XMATCH(deliveries[match_no],_xlfn.ANCHORARRAY(MI_Match_Analysis!$A$2)))*(deliveries[wide]=0))} -> 19 | D11: =IFERROR(B11/C11*100,0) -> 73.684211 | E11: {=SUMPRODUCT((deliveries[batting_team]="MI")*(deliveries[striker]=$A11)*ISNUMBER(_xlfn.XMATCH(deliveries[match_no],_xlfn.ANCHORARRAY(MI_Match_Analysis!$A$2)))*(deliveries[runs_of_bat]=4))} -> 1 | F11: {=SUMPRODUCT((deliveries[batting_team]="MI")*(deliveries[striker]=$A11)*ISNUMBER(_xlfn.XMATCH(deliveries[match_no],_xlfn.ANCHORARRAY(MI_Match_Analysis!$A$2)))*(deliveries[runs_of_bat]=6))} -> 0 | G11: {=SUMPRODUCT((deliveries[batting_team]="MI")*(deliveries[player_dismissed]=$A11)*ISNUMBER(_xlfn.XMATCH(deliveries[match_no],_xlfn.ANCHORARRAY(MI_Match_Analysis!$A$2))))} -> 2 | H11: =IFERROR(B11/G11,0) -> 7 | I11: =B11/7 -> 2
A12: Deepak Chahar | B12: {=SUMPRODUCT((deliveries[batting_team]="MI")*(deliveries[striker]=$A12)*ISNUMBER(_xlfn.XMATCH(deliveries[match_no],_xlfn.ANCHORARRAY(MI_Match_Analysis!$A$2)))*deliveries[runs_of_bat])} -> 6 | C12: {=SUMPRODUCT((deliveries[batting_team]="MI")*(deliveries[striker]=$A12)*ISNUMBER(_xlfn.XMATCH(deliveries[match_no],_xlfn.ANCHORARRAY(MI_Match_Analysis!$A$2)))*(deliveries[wide]=0))} -> 5 | D12: =IFERROR(B12/C12*100,0) -> 120 | E12: {=SUMPRODUCT((deliveries[batting_team]="MI")*(deliveries[striker]=$A12)*ISNUMBER(_xlfn.XMATCH(deliveries[match_no],_xlfn.ANCHORARRAY(MI_Match_Analysis!$A$2)))*(deliveries[runs_of_bat]=4))} -> 1 | F12: {=SUMPRODUCT((deliveries[batting_team]="MI")*(deliveries[striker]=$A12)*ISNUMBER(_xlfn.XMATCH(deliveries[match_no],_xlfn.ANCHORARRAY(MI_Match_Analysis!$A$2)))*(deliveries[runs_of_bat]=6))} -> 0 | G12: {=SUMPRODUCT((deliveries[batting_team]="MI")*(deliveries[player_dismissed]=$A12)*ISNUMBER(_xlfn.XMATCH(deliveries[match_no],_xlfn.ANCHORARRAY(MI_Match_Analysis!$A$2))))} -> 0 | H12: =IFERROR(B12/G12,0) -> 0 | I12: =B12/7 -> 0.85714286
A13: Trent Boult | B13: {=SUMPRODUCT((deliveries[batting_team]="MI")*(deliveries[striker]=$A13)*ISNUMBER(_xlfn.XMATCH(deliveries[match_no],_xlfn.ANCHORARRAY(MI_Match_Analysis!$A$2)))*deliveries[runs_of_bat])} -> 1 | C13: {=SUMPRODUCT((deliveries[batting_team]="MI")*(deliveries[striker]=$A13)*ISNUMBER(_xlfn.XMATCH(deliveries[match_no],_xlfn.ANCHORARRAY(MI_Match_Analysis!$A$2)))*(deliveries[wide]=0))} -> 2 | D13: =IFERROR(B13/C13*100,0) -> 50 | E13: {=SUMPRODUCT((deliveries[batting_team]="MI")*(deliveries[striker]=$A13)*ISNUMBER(_xlfn.XMATCH(deliveries[match_no],_xlfn.ANCHORARRAY(MI_Match_Analysis!$A$2)))*(deliveries[runs_of_bat]=4))} -> 0 | F13: {=SUMPRODUCT((deliveries[batting_team]="MI")*(deliveries[striker]=$A13)*ISNUMBER(_xlfn.XMATCH(deliveries[match_no],_xlfn.ANCHORARRAY(MI_Match_Analysis!$A$2)))*(deliveries[runs_of_bat]=6))} -> 0 | G13: {=SUMPRODUCT((deliveries[batting_team]="MI")*(deliveries[player_dismissed]=$A13)*ISNUMBER(_xlfn.XMATCH(deliveries[match_no],_xlfn.ANCHORARRAY(MI_Match_Analysis!$A$2))))} -> 1 | H13: =IFERROR(B13/G13,0) -> 1 | I13: =B13/7 -> 0.14285714
A14: Jasprit Bumrah | B14: {=SUMPRODUCT((deliveries[batting_team]="MI")*(deliveries[striker]=$A14)*ISNUMBER(_xlfn.XMATCH(deliveries[match_no],_xlfn.ANCHORARRAY(MI_Match_Analysis!$A$2)))*deliveries[runs_of_bat])} -> 7 | C14: {=SUMPRODUCT((deliveries[batting_team]="MI")*(deliveries[striker]=$A14)*ISNUMBER(_xlfn.XMATCH(deliveries[match_no],_xlfn.ANCHORARRAY(MI_Match_Analysis!$A$2)))*(deliveries[wide]=0))} -> 7 | D14: =IFERROR(B14/C14*100,0) -> 100 | E14: {=SUMPRODUCT((deliveries[batting_team]="MI")*(deliveries[striker]=$A14)*ISNUMBER(_xlfn.XMATCH(deliveries[match_no],_xlfn.ANCHORARRAY(MI_Match_Analysis!$A$2)))*(deliveries[runs_of_bat]=4))} -> 1 | F14: {=SUMPRODUCT((deliveries[batting_team]="MI")*(deliveries[striker]=$A14)*ISNUMBER(_xlfn.XMATCH(deliveries[match_no],_xlfn.ANCHORARRAY(MI_Match_Analysis!$A$2)))*(deliveries[runs_of_bat]=6))} -> 0 | G14: {=SUMPRODUCT((deliveries[batting_team]="MI")*(deliveries[player_dismissed]=$A14)*ISNUMBER(_xlfn.XMATCH(deliveries[match_no],_xlfn.ANCHORARRAY(MI_Match_Analysis!$A$2))))} -> 1 | H14: =IFERROR(B14/G14,0) -> 7 | I14: =B14/7 -> 1
A15: Quinton de Kock | B15: {=SUMPRODUCT((deliveries[batting_team]="MI")*(deliveries[striker]=$A15)*ISNUMBER(_xlfn.XMATCH(deliveries[match_no],_xlfn.ANCHORARRAY(MI_Match_Analysis!$A$2)))*deliveries[runs_of_bat])} -> 132 | C15: {=SUMPRODUCT((deliveries[batting_team]="MI")*(deliveries[striker]=$A15)*ISNUMBER(_xlfn.XMATCH(deliveries[match_no],_xlfn.ANCHORARRAY(MI_Match_Analysis!$A$2)))*(deliveries[wide]=0))} -> 81 | D15: =IFERROR(B15/C15*100,0) -> 162.96296 | E15: {=SUMPRODUCT((deliveries[batting_team]="MI")*(deliveries[striker]=$A15)*ISNUMBER(_xlfn.XMATCH(deliveries[match_no],_xlfn.ANCHORARRAY(MI_Match_Analysis!$A$2)))*(deliveries[runs_of_bat]=4))} -> 9 | F15: {=SUMPRODUCT((deliveries[batting_team]="MI")*(deliveries[striker]=$A15)*ISNUMBER(_xlfn.XMATCH(deliveries[match_no],_xlfn.ANCHORARRAY(MI_Match_Analysis!$A$2)))*(deliveries[runs_of_bat]=6))} -> 9 | G15: {=SUMPRODUCT((deliveries[batting_team]="MI")*(deliveries[player_dismissed]=$A15)*ISNUMBER(_xlfn.XMATCH(deliveries[match_no],_xlfn.ANCHORARRAY(MI_Match_Analysis!$A$2))))} -> 2 | H15: =IFERROR(B15/G15,0) -> 66 | I15: =B15/7 -> 18.857143
A16: Danish Malewar | B16: {=SUMPRODUCT((deliveries[batting_team]="MI")*(deliveries[striker]=$A16)*ISNUMBER(_xlfn.XMATCH(deliveries[match_no],_xlfn.ANCHORARRAY(MI_Match_Analysis!$A$2)))*deliveries[runs_of_bat])} -> 2 | C16: {=SUMPRODUCT((deliveries[batting_team]="MI")*(deliveries[striker]=$A16)*ISNUMBER(_xlfn.XMATCH(deliveries[match_no],_xlfn.ANCHORARRAY(MI_Match_Analysis!$A$2)))*(deliveries[wide]=0))} -> 5 | D16: =IFERROR(B16/C16*100,0) -> 40 | E16: {=SUMPRODUCT((deliveries[batting_team]="MI")*(deliveries[striker]=$A16)*ISNUMBER(_xlfn.XMATCH(deliveries[match_no],_xlfn.ANCHORARRAY(MI_Match_Analysis!$A$2)))*(deliveries[runs_of_bat]=4))} -> 0 | F16: {=SUMPRODUCT((deliveries[batting_team]="MI")*(deliveries[striker]=$A16)*ISNUMBER(_xlfn.XMATCH(deliveries[match_no],_xlfn.ANCHORARRAY(MI_Match_Analysis!$A$2)))*(deliveries[runs_of_bat]=6))} -> 0 | G16: {=SUMPRODUCT((deliveries[batting_team]="MI")*(deliveries[player_dismissed]=$A16)*ISNUMBER(_xlfn.XMATCH(deliveries[match_no],_xlfn.ANCHORARRAY(MI_Match_Analysis!$A$2))))} -> 2 | H16: =IFERROR(B16/G16,0) -> 1 | I16: =B16/7 -> 0.28571429
A17: Krish Bhagat | B17: {=SUMPRODUCT((deliveries[batting_team]="MI")*(deliveries[striker]=$A17)*ISNUMBER(_xlfn.XMATCH(deliveries[match_no],_xlfn.ANCHORARRAY(MI_Match_Analysis!$A$2)))*deliveries[runs_of_bat])} -> 7 | C17: {=SUMPRODUCT((deliveries[batting_team]="MI")*(deliveries[striker]=$A17)*ISNUMBER(_xlfn.XMATCH(deliveries[match_no],_xlfn.ANCHORARRAY(MI_Match_Analysis!$A$2)))*(deliveries[wide]=0))} -> 15 | D17: =IFERROR(B17/C17*100,0) -> 46.666667 | E17: {=SUMPRODUCT((deliveries[batting_team]="MI")*(deliveries[striker]=$A17)*ISNUMBER(_xlfn.XMATCH(deliveries[match_no],_xlfn.ANCHORARRAY(MI_Match_Analysis!$A$2)))*(deliveries[runs_of_bat]=4))} -> 0 | F17: {=SUMPRODUCT((deliveries[batting_team]="MI")*(deliveries[striker]=$A17)*ISNUMBER(_xlfn.XMATCH(deliveries[match_no],_xlfn.ANCHORARRAY(MI_Match_Analysis!$A$2)))*(deliveries[runs_of_bat]=6))} -> 0 | G17: {=SUMPRODUCT((deliveries[batting_team]="MI")*(deliveries[player_dismissed]=$A17)*ISNUMBER(_xlfn.XMATCH(deliveries[match_no],_xlfn.ANCHORARRAY(MI_Match_Analysis!$A$2))))} -> 1 | H17: =IFERROR(B17/G17,0) -> 7 | I17: =B17/7 -> 1
A18: Ashwani Kumar | B18: {=SUMPRODUCT((deliveries[batting_team]="MI")*(deliveries[striker]=$A18)*ISNUMBER(_xlfn.XMATCH(deliveries[match_no],_xlfn.ANCHORARRAY(MI_Match_Analysis!$A$2)))*deliveries[runs_of_bat])} -> 1 | C18: {=SUMPRODUCT((deliveries[batting_team]="MI")*(deliveries[striker]=$A18)*ISNUMBER(_xlfn.XMATCH(deliveries[match_no],_xlfn.ANCHORARRAY(MI_Match_Analysis!$A$2)))*(deliveries[wide]=0))} -> 6 | D18: =IFERROR(B18/C18*100,0) -> 16.666667 | E18: {=SUMPRODUCT((deliveries[batting_team]="MI")*(deliveries[striker]=$A18)*ISNUMBER(_xlfn.XMATCH(deliveries[match_no],_xlfn.ANCHORARRAY(MI_Match_Analysis!$A$2)))*(deliveries[runs_of_bat]=4))} -> 0 | F18: {=SUMPRODUCT((deliveries[batting_team]="MI")*(deliveries[striker]=$A18)*ISNUMBER(_xlfn.XMATCH(deliveries[match_no],_xlfn.ANCHORARRAY(MI_Match_Analysis!$A$2)))*(deliveries[runs_of_bat]=6))} -> 0 | G18: {=SUMPRODUCT((deliveries[batting_team]="MI")*(deliveries[player_dismissed]=$A18)*ISNUMBER(_xlfn.XMATCH(deliveries[match_no],_xlfn.ANCHORARRAY(MI_Match_Analysis!$A$2))))} -> 0 | H18: =IFERROR(B18/G18,0) -> 0 | I18: =B18/7 -> 0.14285714

Sheet Bowling_Analysis
A1: Bowler | B1: Overs | C1: Runs Conceded | D1: Wickets | E1: Economy | F1: Dot Balls | G1: 4s Conceded | H1: 6s Conceded | J1: Metrics | K1: Values
A2: {=_xlfn.UNIQUE(_xlfn._xlws.FILTER(deliveries[bowler],(deliveries[bowling_team]="MI")*ISNUMBER(_xlfn.XMATCH(deliveries[match_no],_xlfn.ANCHORARRAY(MI_Match_Analysis!$A$2)))))} -> Trent Boult | B2: {=_xlfn.LET(_xlpm.n,SUMPRODUCT((deliveries[bowling_team]="MI")*(deliveries[bowler]=$A2)*ISNUMBER(_xlfn.XMATCH(deliveries[match_no],_xlfn.ANCHORARRAY(MI_Match_Analysis!$A$2)))*(deliveries[wide]=0)*(deliveries[noballs]=0)),INT(_xlpm.n/6)&"."&MOD(_xlpm.n,6))} -> 9.0 | C2: {=SUMPRODUCT((deliveries[bowling_team]="MI")*(deliveries[bowler]=$A2)*ISNUMBER(_xlfn.XMATCH(deliveries[match_no],_xlfn.ANCHORARRAY(MI_Match_Analysis!$A$2)))*(deliveries[runs_of_bat]+deliveries[wide]+deliveries[noballs]))} -> 110 | D2: {=SUMPRODUCT((deliveries[bowling_team]="MI")*(deliveries[bowler]=$A2)*ISNUMBER(_xlfn.XMATCH(deliveries[match_no],_xlfn.ANCHORARRAY(MI_Match_Analysis!$A$2)))*(deliveries[wicket_type]<>"")*(deliveries[wicket_type]<>"runout")*(deliveries[wicket_type]<>"run out")*(deliveries[wicket_type]<>"retired hurt")*(deliveries[wicket_type]<>"obstructing the field"))} -> 1 | E2: {=_xlfn.LET(_xlpm.n,SUMPRODUCT((deliveries[bowling_team]="MI")*(deliveries[bowler]=$A2)*ISNUMBER(_xlfn.XMATCH(deliveries[match_no],_xlfn.ANCHORARRAY(MI_Match_Analysis!$A$2)))*(deliveries[wide]=0)*(deliveries[noballs]=0)),_xlpm.r,C2,IFERROR(_xlpm.r/(_xlpm.n/6),0))} -> 12.222222 | F2: {=SUMPRODUCT((deliveries[bowling_team]="MI")*(deliveries[bowler]=$A2)*ISNUMBER(_xlfn.XMATCH(deliveries[match_no],_xlfn.ANCHORARRAY(MI_Match_Analysis!$A$2)))*(deliveries[runs_of_bat]=0)*(deliveries[wide]=0)*(deliveries[noballs]=0)*(deliveries[byes]=0)*(deliveries[legbyes]=0))} -> 12 | G2: {=SUMPRODUCT((deliveries[bowling_team]="MI")*(deliveries[bowler]=$A2)*ISNUMBER(_xlfn.XMATCH(deliveries[match_no],_xlfn.ANCHORARRAY(MI_Match_Analysis!$A$2)))*(deliveries[runs_of_bat]=4))} -> 6 | H2: {=SUMPRODUCT((deliveries[bowling_team]="MI")*(deliveries[bowler]=$A2)*ISNUMBER(_xlfn.XMATCH(deliveries[match_no],_xlfn.ANCHORARRAY(MI_Match_Analysis!$A$2)))*(deliveries[runs_of_bat]=6))} -> 8 | J2: Most Wickets | K2: =INDEX($A$2:$A$50,MATCH(MAX($D$2:$D$50),$D$2:$D$50,0)) -> AM Ghazanfar
A3: Hardik Pandya | B3: {=_xlfn.LET(_xlpm.n,SUMPRODUCT((deliveries[bowling_team]="MI")*(deliveries[bowler]=$A3)*ISNUMBER(_xlfn.XMATCH(deliveries[match_no],_xlfn.ANCHORARRAY(MI_Match_Analysis!$A$2)))*(deliveries[wide]=0)*(deliveries[noballs]=0)),INT(_xlpm.n/6)&"."&MOD(_xlpm.n,6))} -> 15.0 | C3: {=SUMPRODUCT((deliveries[bowling_team]="MI")*(deliveries[bowler]=$A3)*ISNUMBER(_xlfn.XMATCH(deliveries[match_no],_xlfn.ANCHORARRAY(MI_Match_Analysis!$A$2)))*(deliveries[runs_of_bat]+deliveries[wide]+deliveries[noballs]))} -> 190 | D3: {=SUMPRODUCT((deliveries[bowling_team]="MI")*(deliveries[bowler]=$A3)*ISNUMBER(_xlfn.XMATCH(deliveries[match_no],_xlfn.ANCHORARRAY(MI_Match_Analysis!$A$2)))*(deliveries[wicket_type]<>"")*(deliveries[wicket_type]<>"runout")*(deliveries[wicket_type]<>"run out")*(deliveries[wicket_type]<>"retired hurt")*(deliveries[wicket_type]<>"obstructing the field"))} -> 3 | E3: {=_xlfn.LET(_xlpm.n,SUMPRODUCT((deliveries[bowling_team]="MI")*(deliveries[bowler]=$A3)*ISNUMBER(_xlfn.XMATCH(deliveries[match_no],_xlfn.ANCHORARRAY(MI_Match_Analysis!$A$2)))*(deliveries[wide]=0)*(deliveries[noballs]=0)),_xlpm.r,C3,IFERROR(_xlpm.r/(_xlpm.n/6),0))} -> 12.666667 | F3: {=SUMPRODUCT((deliveries[bowling_team]="MI")*(deliveries[bowler]=$A3)*ISNUMBER(_xlfn.XMATCH(deliveries[match_no],_xlfn.ANCHORARRAY(MI_Match_Analysis!$A$2)))*(deliveries[runs_of_bat]=0)*(deliveries[wide]=0)*(deliveries[noballs]=0)*(deliveries[byes]=0)*(deliveries[legbyes]=0))} -> 25 | G3: {=SUMPRODUCT((deliveries[bowling_team]="MI")*(deliveries[bowler]=$A3)*ISNUMBER(_xlfn.XMATCH(deliveries[match_no],_xlfn.ANCHORARRAY(MI_Match_Analysis!$A$2)))*(deliveries[runs_of_bat]=4))} -> 21 | H3: {=SUMPRODUCT((deliveries[bowling_team]="MI")*(deliveries[bowler]=$A3)*ISNUMBER(_xlfn.XMATCH(deliveries[match_no],_xlfn.ANCHORARRAY(MI_Match_Analysis!$A$2)))*(deliveries[runs_of_bat]=6))} -> 9 | J3: Best Economy (10+ overs) | K3: {=_xlfn.LET( _xlpm.p,$A$2:$A$50, _xlpm.o,IFERROR(VALUE($B$2:$B$50),0), _xlpm.e,$E$2:$E$50, INDEX(_xlpm.p,MATCH(MIN(_xlfn._xlws.FILTER(_xlpm.e,_xlpm.o>=10)),_xlpm.e,0)) )} -> Jasprit Bumrah
A4: AM Ghazanfar | B4: {=_xlfn.LET(_xlpm.n,SUMPRODUCT((deliveries[bowling_team]="MI")*(deliveries[bowler]=$A4)*ISNUMBER(_xlfn.XMATCH(deliveries[match_no],_xlfn.ANCHORARRAY(MI_Match_Analysis!$A$2)))*(deliveries[wide]=0)*(deliveries[noballs]=0)),INT(_xlpm.n/6)&"."&MOD(_xlpm.n,6))} -> 16.5 | C4: {=SUMPRODUCT((deliveries[bowling_team]="MI")*(deliveries[bowler]=$A4)*ISNUMBER(_xlfn.XMATCH(deliveries[match_no],_xlfn.ANCHORARRAY(MI_Match_Analysis!$A$2)))*(deliveries[runs_of_bat]+deliveries[wide]+deliveries[noballs]))} -> 145 | D4: {=SUMPRODUCT((deliveries[bowling_team]="MI")*(deliveries[bowler]=$A4)*ISNUMBER(_xlfn.XMATCH(deliveries[match_no],_xlfn.ANCHORARRAY(MI_Match_Analysis!$A$2)))*(deliveries[wicket_type]<>"")*(deliveries[wicket_type]<>"runout")*(deliveries[wicket_type]<>"run out")*(deliveries[wicket_type]<>"retired hurt")*(deliveries[wicket_type]<>"obstructing the field"))} -> 8 | E4: {=_xlfn.LET(_xlpm.n,SUMPRODUCT((deliveries[bowling_team]="MI")*(deliveries[bowler]=$A4)*ISNUMBER(_xlfn.XMATCH(deliveries[match_no],_xlfn.ANCHORARRAY(MI_Match_Analysis!$A$2)))*(deliveries[wide]=0)*(deliveries[noballs]=0)),_xlpm.r,C4,IFERROR(_xlpm.r/(_xlpm.n/6),0))} -> 8.6138614 | F4: {=SUMPRODUCT((deliveries[bowling_team]="MI")*(deliveries[bowler]=$A4)*ISNUMBER(_xlfn.XMATCH(deliveries[match_no],_xlfn.ANCHORARRAY(MI_Match_Analysis!$A$2)))*(deliveries[runs_of_bat]=0)*(deliveries[wide]=0)*(deliveries[noballs]=0)*(deliveries[byes]=0)*(deliveries[legbyes]=0))} -> 34 | G4: {=SUMPRODUCT((deliveries[bowling_team]="MI")*(deliveries[bowler]=$A4)*ISNUMBER(_xlfn.XMATCH(deliveries[match_no],_xlfn.ANCHORARRAY(MI_Match_Analysis!$A$2)))*(deliveries[runs_of_bat]=4))} -> 10 | H4: {=SUMPRODUCT((deliveries[bowling_team]="MI")*(deliveries[bowler]=$A4)*ISNUMBER(_xlfn.XMATCH(deliveries[match_no],_xlfn.ANCHORARRAY(MI_Match_Analysis!$A$2)))*(deliveries[runs_of_bat]=6))} -> 8 | J4: Most Dot Balls | K4: =INDEX($A$2:$A$50,MATCH(MAX($F$2:$F$50),$F$2:$F$50,0)) -> Jasprit Bumrah
